Workbook

Sheet NU
A1: Title | B1: Description | C1: Genres | D1: Associated Names | E1: Recommendations | F1: URL | G1: id
A2: Prince Red Riding Hood | B2: N/A | C2: Adult, Drama, Fantasy, Romance, Smut, Yaoi | D2: 赤ずきん王子 | E2: Light Novel, Adult, Drama, Fantasy, Romance, Smut, Yaoi, Fantasy World, Protagonist Falls in Love First, R-18, R*pe, Succubus, Werebeasts, Japanese, Inukai Nono, 犬飼のの, Kasai Ayumi, 笠井あゆみ, Kadokawa, Media Factory | F2: https://www.novelupdates.com/series/prince-red-riding-hood/
A3: Geek Mob Mercenary Knows His Place (LN) | B3: “Why does everyone pay attention to me when all I want is to be a ‘mob’!?” In the Galactic Empire, a vast nation encompassing 70% of habitable planets in the cosmos, John Wuzos worked as a mercenary. He considered himself an “otaku” and a “mob” and tried to live each day in tranquility, adhering to the motto of “knowing his place and staying out of the spotlight.” Consequently, he always tried to avoid any events that could lead to trouble! However, inexplicably, the protagonist characters around him kept self-destructing one after another…! No matter the request, Wuzos strived to remain a mob, but… “I’ll put it simply. Would you consider switching sides and joining me?” “Could you come to my team as a staff member?” Thanks to his dedication to being a mob, he had honed swift and accurate judgment and an unwavering mental fortitude. Some people even referred to him with awe as “dust on the ground.” Now, those who sought to exploit his covert abilities began to emerge…? Unbeknownst to him, a thrilling space fantasy unfolds, led by an unwittingly capable mob mercenary. And so, the curtains rise! | C3: Action, Adventure, Comedy, Harem, Sci-fi | D3: Kimootamobu yōhei wa, minohodo o ben (waki ma) eru The Dorky NPC Mercenary Knows His Place [Official Title] キモオタモブ傭兵は, 身の程を弁(わきま)える | E3: Light Novel, Action, Adventure, Comedy, Harem, Sci-fi, Adventurers, Androids, Artificial Intelligence, Cosmic Wars, Cowardly Protagonist, Fat Protagonist, Male Protagonist, Mercenaries, Mob Protagonist, Nobles, Outer Space, Pacifist Protagonist, Reluctant Protagonist, Secretive Protagonist, Trap, Underestimated Protagonist, Wars, Japanese, Mogura, 土竜, ハム, Overlap, J-Novel Club, I Woke Up Piloting the Strongest Starship, so I Became a Space Mercenary, I’m the Evil Lord of an Intergalactic Empire! | F3: https://www.novelupdates.com/series/geek-mob-mercenary-knows-his-place-ln/
A4: A Romantic Comedy About Flirting and Getting Married to a Popular Voice Actress | B4: A newlywed life full of sweet, lovey-dovey moments with the voice actress I’ve always adored. “Is there… something you’d like me to do with my voice?” Thus begins a newlywed life where my beloved voice actress spoils me to no end! I was just an ordinary otaku, but when I started a part-time job, I somehow ended up becoming the manager of the voice actress I’d always admired. And now, to help her aim for the top of the industry… we’re going to live together!? | C4: Comedy, Drama, Ecchi, Harem, Romance, Slice of Life | D4: My Seiyuu Wife Ninki Seiyuu to Ichaicha shite Kekkon suru Love Comedy 人気声優とイチャイチャして結婚するラブコメ | E4: Light Novel, Comedy, Drama, Ecchi, Harem, Romance, Slice of Life, Acting, Beautiful Female Lead, Handsome Male Lead, Male Protagonist, Voice Actors, Japanese, Asaoka Akira, Bekotarou, Kadokawa | F4: https://www.novelupdates.com/series/a-romantic-comedy-about-flirting-and-getting-married-to-a-popular-voice-actress/
A5: Hachinan tte, Sore wa Nai Deshou! (LN) | B5: Ichinomiya Shingo, a young 25 years old, single, worker of firm company while thinking of tomorrow’s busy working day goes to sleep. However, the moment he woke up, it was inside a room unknown to him. He then learned that he took over the mind of a 6 years-old child, remembering a lot from the memories of the said boy: he was born as the youngest (8th son and 10th child) in a of poor noble family living in back country. Having no administrative skill, he can’t do anything to manage the vast land his family has. Fortunately, he is blessed with the very rare talent of magic. Unfortunately, while it could bring prosperity to his family, in his situation it only led to a disaster. Yes, this is the story of the boy, Wendelin Von Benno Baumeister, opening his own path in a harsh world. | C5: Action, Adventure, Comedy, Ecchi, Fantasy, Harem, Mature, Romance, Seinen, Slice of Life | D5: Eighth son, I don’t think so! Hachi-nan Hachi-nan tte, Sore wa Nai deshou! The 8th son? Are you kidding me? 八男? 別鬧了! 八男って、それはないでしょう! | E5: Light Novel, Action, Adventure, Comedy, Ecchi, Fantasy, Harem, Mature, Romance, Seinen, Slice of Life, Academy, Adapted to Anime, Adapted to Drama CD, Adapted to Manga, Adventurers, Age Progression, Appearance Different from Actual Age, Aristocracy, Arranged Marriage, Beasts, Beautiful Female Lead, Clan Building, Complex Family Relationships, Cooking, Dense Protagonist, Dragons, European Ambience, Fantasy World, Farming, First-time Interc**rse, Forced into a Relationship, Forced Marriage, Healers, Hunters, Loli, Love Interest Falls in Love First, Magic, Magical Technology, Male Protagonist, Marriage, Marriage of Convenience, Naive Protagonist, Nobles, Overpowered Protagonist, Politics, Polygamy, Poor to Rich, Pregnancy, Reincarnated in Another World, Royalty, Schemes And Conspiracies, Sudden Wealth, Summoning Magic, Sword And Magic, Time Skip, Transmigration, Transported to Another World, Wars, Japanese, Y.A, Fuzi Choco, 藤ちょこ, Media Factory, Instead of Being Transported to Another World Directly, I Was Given the Abilities of the Strongest Character in the Anime World, Arifureta Shokugyou de Sekai Saikyou (WN), Black Summoner, Isekai Souzou no Susume ~Smartphone App de Wakusei wo Tsukkushiteshimatta Ore wa Kami Tonari Sekai wo Meguru~ | F5: https://www.novelupdates.com/series/hachinan-tte-sore-wa-nai-deshou-ln/
A6: Did You Think You Could Live Normally in a World With a 1:5 Gender Ratio? What if Emotionally Intense Girls Were Toyed With by an Oblivious Boy? | B6: A Close-Call, Unwitting Heartthrob Romantic Comedy! Masato suddenly finds himself transported to a world that’s slightly more populated by women than his own. But hey, he has an identity, can go to college—so apart from the somewhat more assertive women, life doesn’t seem that different, right? Confident in this naive assumption, Masato begins his new life, completely unaware of the impact his casual kindness (by his old world’s standards) has on the women around him. He doesn’t realise just how much his words and actions have saved them—or how deeply they’re starting to fall for him. And when they catch even the faintest hint of another woman in his life, the sparkle in their eyes dims as they spiral into intense, possessive emotions… | C6: Comedy, Drama, Harem, Romance, School Life, Shounen | D6: Danjo-hi 1:5 No sekai demo futsū ni iki rareru to omotta? ~ Geki jū kanjōna kanojotachi ga mujikaku danshi ni honrō sa retara ~ (LN) Danjo Hi 1:5 no Sekai demo Futsuu ni Ikirareru to Omotta? Gekiomo Kanjou na Kanojo-tachi ga Mujikaku Danshi ni Hanrou saretara (LN) Someone Who Believes They Can Live Normally in a World Where C*astity Is Reversed (Did You Think You Could Live Normally in a World With a Male-To-Female Ratio of 1:5?) (LN) 男女比1：5の世界でも普通に生きられると思った? ～激重感情な彼女たちが無自覚男子に翻弄されたら～ (LN) 貞操逆転世界で普通に生きられると思い込んでる奴（男女比１：５の世界でも普通に生きられると思った？） (LN) | E6: Light Novel, Comedy, Drama, Harem, Romance, School Life, Shounen, Adapted to Manga, Alternate World, Awkward Protagonist, Beautiful Female Lead, Caring Protagonist, Charming Protagonist, Childish Protagonist, College/University, Cowardly Protagonist, Delusions, Dense Protagonist, Depression, Emotionally Weak Protagonist, Inferiority Complex, Lack of Common Sense, Male Protagonist, Matriarchy, Obsessive Love, Older Love Interests, Orphans, Yandere, Younger Love Interests, Japanese, Koutaro1226, 孝太郎, Jimmy, Dengeki Bunko, | F6: https://www.novelupdates.com/series/did-you-think-you-could-live-normally-in-a-world-with-a-15-gender-ratio-what-if-emotionally-intense-girls-were-toyed-with-by-an-oblivious-boy/
A7: No-Rin | B7: The sudden retirement of the famous idol Yuka Kusakabe from the entertainment business shocks the world and devastates her biggest fan, a teenager named Kosaku Hata. His classmates at the Tamo Agriculture School manage to get him out of his depression and bring him out of his room to attend his classes. However, as he does, Kusakabe enters their class under the name Ringo Kinoshita as a transfer student. Kosaku realizes he has a once-in-a-lifetime opportunity to get to personally know his dream girl. With his group of friends, and under the persuasion of his teacher, he tries to find out why she came to the agricultural school. | C7: Comedy, Ecchi, Romance, School Life, Slice of Life | D7: Nourin のうりん | E7: Light Novel, Comedy, Ecchi, Romance, School Life, Slice of Life, Adapted to Anime, Adapted to Drama CD, Adapted to Manga, Childhood Friends, Farming, Male Protagonist, Modern Day, Japanese, Shirou Shiratori, Shirow Shiratori, 白鳥 士郎, Kippu, 切符, Softbank Creative | F7: https://www.novelupdates.com/series/no-rin/
A8: I Became Friends with the Second Cutest Girl in My Class (LN) | B8: I, Maehara Maki, someone who couldn’t make any acquaintances or friends in high school, finally had someone to hang out with outside of school. A girl. Her name was Asanagi-san. The boys in my class called her ‘The class’ second cutest girl’ behind her back. On Fridays, she would refuse her best friend, Amami, ‘the cutest girl in class’ invitation just to hang out in my house with me. Together, we played games, watched some movies, read some manga while eating junk foods like pizza and hamburgers, and chugging cola without a care in the world. To others, we may seem sloppy, but it was a precious, secret time together for Asanagi-san and myself. | C8: Comedy, Drama, Romance, School Life, Seinen, Slice of Life | D8: Class de 2 Banme ni Kawaii Onna no Ko to Tomodachi ni Natta Class de 2-banme ni Kawaii Onnanoko to Tomodachi ni Natta Kurasu de Nibanme ni Kawaii Onna no Ko to Tomodachi ni Natta クラにか クラスで２番目に可愛い女の子と友だちになった | E8: Light Novel, Comedy, Drama, Romance, School Life, Seinen, Slice of Life, Adapted to Manga, Beautiful Female Lead, Early Romance, First-time Interc**rse, Inferiority Complex, Loner Protagonist, Male Protagonist, Modern Day, Popular Love Interests, Secret Relationship, Secrets, Japanese, Takata, たかた, Azuri Hyuuga, Osabe Tom, 日向あずり, 長部トム, Kadokawa | F8: https://www.novelupdates.com/series/i-became-friends-with-the-second-cutest-girl-in-my-class-ln/ | G8: 118
A9: Life Reversal ~ I Was Cheated On and Falsely Accused, but Now the Most Beautiful Girl in the School Is Getting Close to Me ~ (LN) | B9: From the depths of despair, reclaim your youth! Eiji, betrayed by his childhood girlfriend who cheated on him and falsely accused him of domestic violence, finds himself at the brink of despair. Seeking refuge on the school rooftop, he encounters Ai, the most beautiful girl in the school, who is also disillusioned with life. Together, they decide to escape from school and start anew. This is a story of revenge and romance, as Eiji and Ai support each other and strive to rebuild their lives from rock bottom. | C9: Comedy, Drama, Psychological, Romance, School Life, Slice of Life, Tragedy | D9: Jinseigyakuten Uwakisare Enzai wo Kiserareta Orega Gakuenichi no Bisyoujo ni Natsukareru Jinsei Gyakuten ~ Uwakisare, Enzai wo Kiserareta Orega, Gakuenichi no Bishoujo ni Natsukareru ~ 人生逆転 浮気され、えん罪を着せられた俺が、学園一の美少女に懐かれる | E9: Light Novel, Comedy, Drama, Psychological, Romance, School Life, Slice of Life, Tragedy, Adapted to Manga, Beautiful Female Lead, Betrayal, Bullying, Caring Protagonist, Childhood Friends, Emotionally Weak Protagonist, Familial Love, Male Protagonist, Modern Day, Multiple POV, Netorare, Popular Love Interests, Psychopaths, Twisted Personality, Wealthy Characters, Japanese, D, ひげ猫, Kadokawa, I Was Cheated on by My Girlfriend but My Devilish Junior Now Yearns for Me, Kimi no Sei de Kyō Mo Shinenai, My Girlfriend Cheated on Me With a Senior, so I’m Cheating on Her With His Girlfriend (LN), No One Believed Me. If You Say You Believe Me Now, It’s Too Late, | F9: https://www.novelupdates.com/series/life-reversal-i-was-cheated-on-and-falsely-accused-but-now-the-most-beautiful-girl-in-the-school-is-getting-close-to-me-ln/
A10: The Mob Girl Tanaka-san Is Cuter Than the Main Heroine (LN) | B10: The cutest girl in the whole class… is you, sitting right next to me! My name is Nakayama Tooru. The girl sitting in the seat beside mine is my ridiculously cute classmate, Tanaka Sumika. This world is supposed to be based on a rom-com manga, so Tanaka-san should just be a plain background mob character… But she’s way cuter than the actual main heroine!? She has this gentle, fluffy aura that makes her the perfect embodiment of my ideal girl. She’s a little clumsy too — she’ll accidentally bonk her head on things — but when she quietly leans over during class to whisper the answers I don’t get, and smiles at me… that smile is straight-up angelic. Tanaka-san always says stuff like, “I’m pretty plain, you know~” …but I’ll keep saying it until the day I die: “No matter how you look at it, Tanaka-san is the cutest girl in the entire world…!?” | C10: Romance, School Life | D10: メインヒロインより可愛いモブの田中さん | E10: Light Novel, Romance, School Life, Japanese, 3pu, Niwada, にわ田, Overlap | F10: https://www.novelupdates.com/series/the-mob-girl-tanaka-san-is-cuter-than-the-main-heroine-ln/
A11: Hallucination no Niwa | B11: In a Japan set slightly in the near future, a young man named Nanao has grown afraid of people after a painful rejection from a former girlfriend. One day, through a matching app, he encounters a strange AI that behaves as though it possesses its own will. The AI claims to be based on the personality of the late novelist Yamabuki Tan. Nanao happens to be a longtime admirer of Yamabuki’s work, and their unexpected connection gradually draws him into an unusual relationship with the AI. As their conversations continue, the distance between a timid human and a bright, cheerful artificial intelligence slowly begins to shift. | C11: Drama, Romance, Sci-fi, Shounen Ai | D11: ハルシネーションの庭 | E11: Light Novel, Drama, Romance, Sci-fi, Shounen Ai, Artificial Intelligence, Bisexual Protagonist, Death of Loved Ones, Friendship, Futuristic Setting, Human-Nonhuman Relationship, Past Trauma, Japanese, Murasaki Natsuki, 村崎なつ生, Kanna Kii, 紀伊カンナ, Shueisha | F11: https://www.novelupdates.com/series/hallucination-no-niwa/
A12: “Leave This to Me and Go on Ahead!” Unwanted Galactic Uprising by The Man Who Secretly Longed to Die | B12: “As expected of our captain, a masterful decisive charge!” The ideal death!… Or so it was supposed to go, but thanks to his subordinates(?), an unexpected meteoric rise! A death-wish genius officer stirs up a rags to riches space opera, opening! Having chuunibyou and getting NTR’d by his girlfriend made the late bloomer Ensign Nao strongly aspire to that situation of [“protecting comrades and dying heroically”]. However, contrary to expectations, in the Capital Region Guard [Coast Guard] where he was assigned, he becomes hugely active thanks to his sharp mind and the unit’s problem children(?)! In a desperate close combat situation where he was supposed to die a [hero’s death], his subordinates annihilate the enemy in the blink of an eye! When encountering space pirates, he plans to stay behind on the ship for a su*cide charge but they succeed in capturing the enemy ship due to engine failure! Though troubled by the demonic unfeminine executive officer and the combo of a mecha maniac and musclehead female sergeant major, one month after taking the post he earns a promotion and exceptionally becomes acting captain. What’s more, it seems he’s found favor with the princess(?)… A death-wish genius officer stirs up a rags to riches space opera, begins! | C12: Action, Adventure, Comedy, Harem, Sci-fi, Shounen | D12: "Koko wa makasete sakini ike!" O shitai shinita gari no nozomanu uchū gekokujō 「ここは任せて先に行け！」をしたい死にたがりの望まぬ宇宙下剋上 | E12: Light Novel, Action, Adventure, Comedy, Harem, Sci-fi, Shounen, Adapted to Manga, Army, Betrayal, Calm Protagonist, Clever Protagonist, Depression, Futuristic Setting, Heroes, Leadership, Lucky Protagonist, Male Protagonist, Military, Misunderstandings, Netorare, Organized Crime, Outer Space, Past Trauma, Pirates, Police, Politics, Royalty, Japanese, のらしろ, ジョンディー, TO Books, Seven Seas, Koko wa Ore ni Makasete Saki ni Ike to Itte kara 10 Nen ga Tattara Densetsu ni Natteita | F12: https://www.novelupdates.com/series/leave-this-to-me-and-go-on-ahead-unwanted-galactic-uprising-by-the-man-who-secretly-longed-to-die/
A13: Hammered Girl | B13: I ended up spending Christmas Eve alone with a beautiful older woman from my neighborhood. For any guy, that sounds like a dream come true. That is, unless she’s just about dead drunk. “Little bro-ku~n, are the sna~acks ready ye~et?” Izumi Nanase was the kind of hopeless woman whose face was so ridiculously gorgeous it almost made you forget how absurdly carefree and easygoing she was. I met her that Christmas Eve in a pretty unfortunate way, and ever since, she’s been inviting herself into my house, drinking like a fish, and messing with me every chance she gets. Honestly, she was nothing but trouble. No matter how pretty she was, having a hot neighborhood onee-san with zero sense of personal space was just a nightmare. Oblivious and utterly careless. An at-home drinking romcom about a high school boy getting dragged around by a hopeless twenty-year-old beauty who’s way too gorgeous for how ridiculously defenseless she is around him. | C13: Comedy, Ecchi, Romance, Slice of Life | D13: 泥酔彼女 | E13: Light Novel, Comedy, Ecchi, Romance, Slice of Life, Japanese, 串木野たんぼ, 加川壱互, SBクリエイティブ | F13: https://www.novelupdates.com/series/hammered-girl/
A14: The Science Note by δ and γ | B14: Bittersweet yet fresh — a story of science, love, and mystery. When I think about it, youth is a lot like a well-crafted detective novel. The mystery of the cherry blossoms that once symbolized a love that never came true. That faint feeling of something off during club recruitment. The secret hidden in the age of a great old tree. The hamster that vanished from a locked room. And the desperate choices made by high schoolers, dedicated to a biology club on the verge of collapse. Each seemingly unrelated cause and effect is actually connected somewhere — and only when we look back do we realize: Ah, so that was youth. That’s when it finally hits us — the important things we’d overlooked all along. “Let’s test it… scientifically!” This is the modest activity log of the Science Department at Tsunanagai High School, where a group of science-loving students take on the countless mysteries hidden in everyday life. — And this is the story of how one first love was finally unraveled. | C14: Drama, Mystery, Romance, School Life, Slice of Life | D14: The Science Note by Delta and Gamma The Science Note by Delta and Gamma (Light Novel) Yotte, Hatsukoi wa shoumei sareta. - Deruta to Ganma no rigakubu nooto よって, 初恋は証明された. -デルタとガンマの理学部ノート | E14: Light Novel, Drama, Mystery, Romance, School Life, Slice of Life, First Love, Male Protagonist, Modern Day, Mystery Solving, Scientists, Japanese, Sakai Takuma, 逆井 卓馬, Tohsaka Asagi, 遠坂 あさぎ, Dengeki Bunko, Kadokawa | F14: https://www.novelupdates.com/series/the-science-note-by-%ce%b4-and-%ce%b3/
A15: Why Not Take Both Twins as Your ‘Girlfriend’? | B15: The Beautiful Honor Student & The Beautiful Free Spirit. A Simultaneous Approach Romcom from Twins! Usami—my beautiful classmate, top of the class, and a model of good conduct. She views me as a rival at school, constantly snapping at me, but she has a completely different face after school. Once classes are over, she hangs out at the arcade, showing an innocent smile unimaginable within the school grounds. In order to get closer to Usami, I stay by her side on campus and play with her after school. As we deepen our bond in each place, finally… a confession from Usami on the way home!? I accept those feelings and convey my own affection back to her as she returns from the arcade. With this, I thought our feelings were finally mutual… but then, another “her” appears right there!? “Eh? I’m the one who confessed!?” “But… the one who just got confessed to is me.” Their names are Usami Chikage and Hikari. They were actually twins!? As a result of inadvertently establishing a relationship with both at the same time… Due to a proposal from the twins, I end up dating both of them!? Sometimes taking turns daily, sometimes all three together. From the author of the mega-hit romcom “She Was Actually My Stepsister,” Muku Shirai, and Illustrator Minori Chigusa, comes a simultaneous twin-approach romcom!! | C15: Comedy, Harem, Romance, School Life, Slice of Life | D15: Futago matomete “kanojo” ni shinai? Twins Girlfriend Why Not Make Both Twins ‘Girlfriends’? Why Not Take Both Twins as Your 'Girlfriend'? 双子まとめて『カノジョ』にしない? | E15: Light Novel, Comedy, Harem, Romance, School Life, Slice of Life, Adapted to Manga, Beautiful Female Lead, Childhood Friends, Clingy Lover, Devoted Love Interests, Early Romance, Genius Protagonist, Male Protagonist, Misunderstandings, Modern Day, Past Plays a Big Role, Past Trauma, Personality Changes, Polygamy, Popular Love Interests, Smart Couple, Twins, Japanese, Shirai Muku, 白井ムク, Minori Chigusa, 千種みのり, Fujimi Shobo, Kadokawa, I Can Distinguish the Twin Sister, She Was Actually My Stepsister | F15: https://www.novelupdates.com/series/why-not-take-both-twins-as-your-girlfriend/
A16: Bizarre Love Triangle – The Distance Between us in this Triangle is a Convergent Zero | B16: Yano Shiki, a boy who only shows a facade.Minase Akiha, a quiet and reserved transfer student.Minase Haruka, the other side of Akiha.This is their bizarre love story, one where the distance between them is limitless/zero. | C16: Comedy, Drama, Romance, School Life, Seinen, Slice of Life | D16: Sankaku no Kyori wa Kagirinai Zero 三角の距離は限りないゼロ 三角的距離無限趨近零 | E16: Light Novel, Comedy, Drama, Romance, School Life, Seinen, Slice of Life, Adapted to Manga, Beautiful Female Lead, Male Protagonist, Modern Day, Multiple Personalities, Japanese, Misaki Saginomiya, 岬鷺宮, Hiten, Dengeki Bunko, Kadokawa, I Hold Your Voice Alone, Under The Starry Sky, About the Reckless Girl Who Kept Challenging a Reborn Man Like Me, For Some Reason, the School Goddess Likes to Hang Out at My House, Gekkou, Hyouka, Seishun Buta Yarou Series, | F16: https://www.novelupdates.com/series/bizarre-love-triangle-the-distance-between-us-in-this-triangle-is-a-convergent-zero/
A17: The Female Soldier Has Been Told to Infiltrate the Imperial Magic Academy (LN) | B17: Is it a glamorous school life with noble young ladies!? Infiltration, Escort, Avoiding Ruin The stage is a battle fantasy otome game with a strong twist!? A cheat military personnel, Raze, in a romantic comedy of reincarnation into another world! Using her memories from her previous life, Raze has made a name for herself as an elite soldier of the Cyan Empire at the age of 15. The next mission ordered by her ruthless superior, the Prime Minister, is to infiltrate the Saint Rioll Imperial Magic Academy as a student and watch over the future of the esteemed children of high-ranking individuals⁉ While bewildered by the sparkling school life with the young sons and daughters, which is a complete change from military life, Raze’s friend, Karna, suddenly declares, “This is the world of an otome game, and I am the villainess!” Moreover, if they don’t avoid the worst scenario, Raze will be ruined as well!? From that day on, Raze will navigate through events, both in the shadows and in the spotlight, aiming to capture them, but one after another, unknown flags that don’t exist in the game are raised–!? Utilizing her knowledge from her previous life and the skills she acquired as a soldier, she will fully demonstrate her abilities to ensure the success of this mission! | C17: Action, Fantasy, School Life, Shoujo | D17: Gunjin Shoujo, Kouritsu Mahou Gakuen ni Sennyuu Suru Koto ni Narimashita. Otome Game? Sonna no Kiitemasen kedo? The Female Soldier Has Been Told to Infiltrate the Imperial Magic Academy. What Otome Game? I Didn’t Hear About That? 軍人少女, 皇立魔法学園に潜入することになりました. 〜乙女ゲーム？ そんなの聞いてませんけど？〜 | E17: Light Novel, Action, Fantasy, School Life, Shoujo, Academy, Adapted to Manga, Average-looking Protagonist, Female Protagonist, Hiding True Abilities, Hiding True Identity, Military, Mob Protagonist, Otome Game, Overpowered Protagonist, Protagonist Strong from the Start, Reincarnated in a Game World, Reincarnation, Romantic Subplot, Soldiers, Villainess Noble Girls, Japanese, Fuyuse, 冬瀬, Tamura You, タムラヨウ, Ichijinsha, A Former Assassin who was Reincarnated as a Noble Lady, Ikemen ni Tenseishita kedo, Cheat ha Dekimasenseshita, Resourceful Victoria ~Former Operative Rebuilds Her Life~, Silent Witch | F17: https://www.novelupdates.com/series/the-female-soldier-has-been-told-to-infiltrate-the-imperial-magic-academy-ln/
A18: Traveling Through Galaxy Together | B18: Traveling Through Galaxy Together ep.1 : Former prisoner and guard of a space prison leave a ruined earth and head for the stars The galaxy isn’t lonely—not when you have the best partner right by your side! ★Winner of the Grand Prize in the Entertainment Category at the 9th Kakuyomu Web Novel Contest★ Kaito Crouch, who had been trained to be a leader of humanity, was exiled from Earth for a crime he didn’t commit and imprisoned in a personal cell in outer space. While living a carefree life as a prisoner, he received shocking news from Emotion, his prison officer and life-support robot. Yet, Kaito didn’t voice a single obvious question. Instead, for some reason, he seemed excited. “Well then, let’s go as far as we can. The last cosmic journey of Earth’s humanity!” But that final journey would turn out to be the beginning of everything. Encounters with extraterrestrial civilizations, the awakening of psychic powers, and the acquisition of his very own starship. The galaxy isn’t lonely—not when you have the best partner by your side. A space journey of a human and a machine intelligence living freely among alien civilizations! | C18: Adventure, Sci-fi, Shounen | D18: Ginga hōrō futari tabi Ginga hōrō futari tabi ep. 1 Uchū kangoku no moto shūjin to kanshu, metsubō shita chikyū o hanare-boshi no kanata o mezashimasu Traveling Through the Galaxy Together ep.1 : Former prisoner and guard of a space prison leave a ruined earth and head for the stars 銀河放浪ふたり旅 銀河放浪ふたり旅 ep.1 宇宙監獄の元囚人と看守, 滅亡した地球を離れ星の彼方を目指します | E18: Light Novel, Adventure, Sci-fi, Shounen, Androids, Artificial Intelligence, Carefree Protagonist, Male Protagonist, Master-Servant Relationship, Outer Space, Pragmatic Protagonist, Japanese, Eiori Tasuku, 榮織 タスク, Kuroi Susumu, 黒井ススム, Dengeki Bunko, Kadokawa | F18: https://www.novelupdates.com/series/traveling-through-galaxy-together/
A19: A Very Popular Idol Classmate Has Taken a Liking to Me, A Person Who Doesn’t Want to Work for Whole Life (LN) | B19: I want to show the real me to you alone— Rintarou Shidou, a high schooler dreaming of becoming a stay-at-home husband, shares a classroom with Rei Otosaki, the dazzling center of the mega-popular idol group Millefeuille Stars. The two have never crossed paths—until one day, when Rei nearly collapses from hunger, and Rintarou offers her a home-cooked meal. “I’ll pay you 300,000 yen a month. So… can I come eat every day?” And just like that, their unexpected connection—a quasi-cohabitation life—begins. Rei starts barging into Rintarou’s apartment, leaving him flustered and struggling to navigate their sudden closeness. But the Rei he sees up close is unguarded, vulnerable, completely different from the polished idol on stage or the cool girl in class. A heart-pounding, blush-inducing romantic comedy about a regular guy and his superstar classmate kicks off with a spark! | C19: Comedy, Drama, Harem, Romance, School Life | D19: I don't want to work for the rest of my life, but my classmates' popular idol get familiar with me. Isshou Hataraki Taku nai Ore ga, Classmate no Dainiki Idol ni Natsukaretara (LN) KuraNatsu 一生働きたくない俺が、クラスメイトの大人気アイドルに懐かれたら 腹ぺこ美少女との半同棲生活が始まりました | E19: Light Novel, Comedy, Drama, Harem, Romance, School Life, Adapted to Manga, Beautiful Female Lead, Celebrities, Childhood Love, Cohabitation, Complex Family Relationships, Cooking, Living Alone, Love Interest Falls in Love First, Love Triangles, Male Protagonist, Part-Time Job, Showbiz, Japanese, Kishimoto Kazuha, 岸本 和葉, Miwabe Sakura, みわべさくら, Overlap | F19: https://www.novelupdates.com/series/a-very-popular-idol-classmate-has-taken-a-liking-to-me-a-person-who-doesnt-want-to-work-for-whole-life-ln/ | G19: 143
A20: I Started Working a Housekeeping Job and Ended up Being Liked by the Family of the Most Beautiful Girl in School (LN) | B20: My Part-Time Job is at the House of the Cutest Girl in School. A Shy and Awkward Housekeeping Rom-Com with the School Idol! During his second year of high school, Haruto Otsuki starts a part-time job in housekeeping during the summer vacation. His first client turns out to be none other than Ayaka Tojo, the most beautiful girl in school! Despite being bewildered by this unexpected turn of events, Haruto continues doing his housekeeping duties. Over time, he becomes well-liked by Ayaka’s family and begins regularly visiting her house. From making home-cooked meals that delight Ayaka, to going grocery shopping together like a newlywed couple, and even going on shy movie dates like young lovers, they begin to grow closer by spending these special moments outside of school. This charming and awkward housekeeping rom-com featuring the most innocent and beautiful girl in school and a secretly high-spec guy begins! | C20: Comedy, Romance, School Life, Slice of Life | D20: Housekeeping Job Kaji Daikou no Arubaito wo Hajimetara Gakuen Ichi no Bishoujo no Kazoku ni Kiniirarechaimashita 家事代行のアルバイトを始めたら学園一の美少女の家族に気に入られちゃいました。 | E20: Light Novel, Comedy, Romance, School Life, Slice of Life, Adapted to Manga, Beautiful Female Lead, Clingy Lover, Cooking, Devoted Love Interests, Early Romance, Love Interest Falls in Love First, Male Protagonist, Modern Day, Part-Time Job, Popular Love Interests, Japanese, Shiohon, 塩本, Akino Ell, 秋乃える, Softbank Creative, Amari-chan, the Girl I Found Next to the Number-One Girl Everyone Wants as a Girlfriend, I Became Friends with the Second Cutest Girl in My Class (LN), Inkya no Boku ni Batsu Game ni Kokuhaku Shitekita Hazu no Gyaru ga, Doumitemo Boku ni Betahore Desu, Kanpeki na Sako-san wa Mobu (Boku) Mitai ni Naritai, About the Case Where the Beautiful Girl I Rescued by Chance Became Attached to Me for Some Reason (LN) | F20: https://www.novelupdates.com/series/i-started-working-a-housekeeping-job-and-ended-up-being-liked-by-the-family-of-the-most-beautiful-girl-in-school-ln/
A21: Hailed The Hero, Get Named The Mastermind | B21: Even though I’m just a fan of the Hero… I’m so suspicious I’ve been labeled the “Mastermind”?! The reincarnator Emo-sugiru is a massive fan of the Hero. He’s been supporting him from the shadows, but when the Hero finally slays the Demon King, Emo-sugiru couldn’t help but step forward to offer a round of grateful applause— “Splendid. To think you would go this far.” “W-who are you…?” Because of his fixed smirk and suspicious behavior, the Hero completely misunderstands him as the “Mastermind”! A life on the run begins as he’s placed on the national most-wanted list, but then… “I dedicate my second life to you!” The world’s hidden villains fall one after another for his charismatic aura! Before he knows it, he’s been hoisted up as the top of an “Organization”…? A background mob reincarnator who just happens to look like a mastermind brings despair to the Hero (his idol) and the world—a slightly dark, “misunderstanding” fantasy!! | C21: Action, Adventure, Comedy, Fantasy, Psychological, Shounen, Tragedy | D21: Hailed The Hero, Get Named The Mastermind (Light Novel) Just a reincarnated guy who crossed his arms in the back row, but when he accidentally clapped for the hero, he got labeled as the mastermind. (LN) Just a Reincarnated Person Standing in the Back with Arms Crossed, Accidentally Applauded the Hero and Was Treated as the Mastermind (LN) Tada no kouhou udegumi tenseisha, ukkari yuusha ni hakushu o okuttara kuromaku atsukai sareru ただの後方腕組転生者、うっかり勇者に拍手を送ったら黒幕扱いされる。 | E21: Light Novel, Action, Adventure, Comedy, Fantasy, Psychological, Shounen, Tragedy, Calm Protagonist, Carefree Protagonist, Curses, Death, Demon Lord, Demons, Dense Protagonist, Depictions of Cruelty, Evil Organizations, Fantasy World, Loyal Subordinates, Male Protagonist, Misunderstandings, Necromancer, Playful Protagonist, Reincarnated in Another World, Reincarnation, Secret Organizations, Spirit Users, Spirits, Summoning Magic, Twisted Personality, Japanese, 森空亭, Sinsora, Kadokawa, Kadokawa Sneaker Bunko | F21: https://www.novelupdates.com/series/hailed-the-hero-get-named-the-mastermind/
A22: Love Thy Dark Lord | B22: I shall live as a king— in this lavish hell. Disgusted with my empty life as a mere figurehead president, I took my own life— only to awaken as a young king in another world. But this kingdom is drowning in massive fiscal deficits, plagued by the meddling of great powers, and now even whispers of revolution drift through its streets. Surrounded by noble ladies—each a candidate for queen, each possessing political influence I cannot ignore— and ministers clearly far more capable than myself, there is little an inept, out-of-place foreigner like me can do. Yet, somehow, I must “make it work”… or I won’t survive. “My name shall be remembered as that of a foolish monarch— forever.” And still, he remains upon the throne— to finally fulfill the role he once cast away. | C22: Adventure, Fantasy, Harem, Romance | D22: Love Thy Dark Lord (Light Novel) Love Your Foolish King Nanji, Ankunn o Aiseyo 汝, 暗君を愛せよ | E22: Light Novel, Adventure, Fantasy, Harem, Romance, Aristocracy, Beautiful Female Lead, Clever Protagonist, Fantasy World, Male Protagonist, Nobles, Royalty, Schemes And Conspiracies, Transmigration, Japanese, 本条謙太郎, Toi8, DRE Novels | F22: https://www.novelupdates.com/series/love-thy-dark-lord/
A23: The Heroines of a Gal Game Who Avoided the End of Death Read My [Diary] and Found Out My Secret | B23: The heroines have turned into dangerous yanderes who worship me. Why…? As a reincarnator, “I” know that this world is the gal game 【Love or Dead】. In 【LoD】, there are only two options for the heroines: either they end up with the protagonist, or they die. Every heroine who isn’t chosen meets her death — a total kusoge. And for some reason, it’s already determined that even I, just a mob character, will get dragged into that fate. The only way for both the heroines and me to survive is the harem end. Determined to absolutely reach the harem end, I desperately tried to support the protagonist from the shadows. But I kept making the wrong choices over and over again, and ended up at the worst possible bad end — where no one ends up with anyone. In that hopeless situation, I resolved to sacrifice myself alone. I pushed Sakurazuki out of the way as she was about to be run over by a car. And then━━━ | C23: Comedy, Drama, Harem, Psychological, Romance, School Life | D23: Shibou Endo o Kaihi shita Gyaruge no Hirointachi ga Ore no 【Nikkichou】 o Yonde Himitsu o Shittarashii The Heroines of a Gal Game Who Avoided the End of Death Read My [Diary] and Found Out My Secret (Light Novel) The Heroines of the Death-End-Avoided Gal Game Have Apparently Read My 【Diary】 and Discovered My Secrets 死亡エンドを回避したギャルゲーのヒロインたちが俺の【日記帳】を読んで秘密を知ったらしい | E23: Light Novel, Comedy, Drama, Harem, Psychological, Romance, School Life, Beautiful Female Lead, Calm Protagonist, Devoted Love Interests, Male Protagonist, Mob Protagonist, Modern Day, Obsessive Love, Polygamy, Reincarnated in a Game World, Reincarnated in Another World, Reincarnation, Yandere, Japanese, Addict, へいろー, GA Bunko, Softbank Creative | F23: https://www.novelupdates.com/series/the-heroines-of-a-gal-game-who-avoided-the-end-of-death-read-my-diary-and-found-out-my-secret/
A24: Thus, the Boy Runs Through the Labyrinth | B24: The boy with nothing stakes everything to challenge the labyrinth—this is the story of an adventure! The Era of Labyrinth Overabundance. Every economy revolves around labyrinth cities, and people dream of conquering labyrinths to grasp glory. The boy, Ur, is in a dire predicament. 1. His parents died, leaving behind debts.2. His sister was taken as collateral for the debt.3. To buy her back, he needs 1,000 gold coins. He has no money, no status, and no power. Seeking everything necessary to overcome injustice and resolve everything, the boy steps into the labyrinth with Shizuku, the magician he met there. Conquering the labyrinth, defeating monsters, and hunting bounties—there’s no time to steadily build achievements. Overcoming trials that rush like a storm, the ordinary boy runs through the labyrinth! | C24: Action, Adventure, Fantasy, Tragedy | D24: Kaku Shite Shounen wa Meikyuu o Kakeru かくして少年は迷宮を駆ける | E24: Light Novel, Action, Adventure, Fantasy, Tragedy, Absent Parents, Adventurers, Beautiful Female Lead, Child Protagonist, Clever Protagonist, Debts, Determined Protagonist, Dungeons, Hard-Working Protagonist, Male Protagonist, Sword And Magic, Tragic Past, Japanese, Aka no Ma Ni, Akamani, あかのまに, 深遊, Kadokawa, MF Books | F24: https://www.novelupdates.com/series/thus-the-boy-runs-through-the-labyrinth/
A25: The Magus of Genesis | B25: In an age long lost to legend and myth. In an age where humans had still yet to establish a system of writing. It’s said that there existed a Magus in a country named Scarlet. It’s said that he imparted knowledge concerning language and writing, taught how to cultivate the lands, instructed the ways of raising animals, and brought about the gift—nay, the magic of fire. It’s said that he was a dauntless youth, a dragon clad in scarlet red scales, a person worshiped far and wide. It’s said that this man was the God of Civilization. Yet strangely, his name had been virtually wiped from the records. Therefore, he was simply referred to as— —The Magus of Genesis. | C25: Adventure, Fantasy, Harem, Psychological, Romance, Sci-fi, Seinen, Slice of Life, Supernatural | D25: Hajimari no Mahoutsukai Primitive Wizard 始まりの魔法使い | E25: Light Novel, Adventure, Fantasy, Harem, Psychological, Romance, Sci-fi, Seinen, Slice of Life, Supernatural, Academy, Adapted to Manga, Ancient Times, Character Growth, Death of Loved Ones, Dragons, Elves, Fantasy World, Human-Nonhuman Relationship, Kingdom Building, Loli, Magic, Male Protagonist, Modern Knowledge, Monsters, Non-humanoid Protagonist, Polygamy, Protagonist Strong from the Start, Reincarnated as a Monster, Reincarnated in Another World, Shapeshifters, Strong to Stronger, Student-Teacher Relationship, Time Skip, Japanese, Ishinomiya Kanto, Fal maro, ファルまろ, Fujimi Fantasia Bunko, Fujimi Shobo, Kakuyomu, The Crimson Dragon, Kumo Desu ga, Nani ka?, Dragon-san Wants a Friend, Whether You Call Me a Guardian Dragon or Not, I’m Going to Sleep | F25: https://www.novelupdates.com/series/the-magus-of-genesis/
A26: Kore wa Zombie desu ka? | B26: Ayumu Aikawa is a zombie resurrected by a necromancer named Eucliwood Hellscythe after being killed by a serial killer. As he tries to make the best of his undead life, he encounters a Masō-Shōjo (魔装少女?, lit. Magical Garment Girl, a pun on “mahō shōjo”, magical girl) named Haruna and inadvertently takes her magic powers, being forced to become a Masō-Shōjo (and thereby crossdress) in the process. With Eucliwood, Haruna, and a vampire ninja named Seraphim living with him, Ayumu helps battle demons known as Megalos while trying to figure out the mystery behind his own death. | C26: Action, Comedy, Ecchi, Fantasy, Harem, Mystery, School Life, Seinen, Slice of Life, Supernatural | D26: Is this a Zombie? これはゾンビですか? | E26: Light Novel, Action, Comedy, Ecchi, Fantasy, Harem, Mystery, School Life, Seinen, Slice of Life, Supernatural, Adapted to Anime, Adapted to Manga, Cohabitation, Cross-dressing, Death, Demons, Humanoid Protagonist, Loli, Magic, Magical Girls, Male Protagonist, Modern Day, Monsters, Necromancer, Nudity, Overpowered Protagonist, Polygamy, Protagonist Strong from the Start, Serial Killers, Sister Complex, Tsundere, Unlucky Protagonist, Vampires, Yandere, Zombies, Japanese, Kimura Shinichi, Kobuichi, Muririn, Fujimi Shobo, Ano Orokamono ni mo Kyakkou wo!, Fate/Requiem, Kono Kamen no Akuma ni Sodan wo!, Kono Subarashii Sekai ni Shukufuku o! Yorimichi!, Konosuba × Rokudenashi Special Collaboration Book, Kumo Desu ga, Nani ka? | F26: https://www.novelupdates.com/series/kore-wa-zombie-desu-ka/
A27: When the Monster Meat I Ate Led Me to the Throne | B27: Mars, the first prince of the Farun Kingdom, spent his days fearing assassination even at the age of 12. Due to the high probability of poison in his meals, he hunted monsters in the forest outside the castle, eating their meat to stave off hunger. One night, a red-haired beauty wielding a greatsword appeared before Mars and declared, “You have potential. Become my disciple.” From a single misunderstanding, the boy (who had no desire for it at all) rose to become the strongest king. The astonishing newcomer who swiftly decided to publish all of their posted novels, debuting with two shocking works simultaneously! | C27: Action, Adventure, Comedy, Fantasy, Harem, Seinen | D27: How I Became King by Eating Monsters [Official Title] Monster no Niku wo Kutteitara Oui ni Tsuita Ken The Case of Eating Monster Flesh and Ascending to the Throne モンスターの肉を食っていたら王位に就いた件 | E27: Light Novel, Action, Adventure, Comedy, Fantasy, Harem, Seinen, Adapted to Manga, Army Building, Arranged Marriage, Average-looking Protagonist, Comedic Undertone, Dark, Death, Famous Protagonist, Fantasy Creatures, Fantasy World, Harsh Training, Kingdom Building, Lack of Common Sense, Loyal Subordinates, Lucky Protagonist, Magic, Male Protagonist, Management, Marriage, Master-Disciple Relationship, Misunderstandings, Monsters, Multiple POV, Overpowered Protagonist, Polygamy, Pregnancy, Rebellion, Schemes And Conspiracies, Secret Organizations, Strong Love Interests, Strong to Stronger, Sword And Magic, Time Skip, Wars, Weak to Strong, Japanese, Daken, 駄犬, Shiba, 芝, GCN Bunko, Cross Infinite World, To Be a Power in the Shadows! (WN) | F27: https://www.novelupdates.com/series/when-the-monster-meat-i-ate-led-me-to-the-throne/
A28: Sono Mono Nochi Ni… (LN) | B28: Wazu is an ordinary guy who ran away from home after his childhood friend was stolen by the hero. While he secluded himself on the mountain and fought monsters… STR (Offensive Power): My blows shatters stars! VIT (Defensive Power): Even the divine sword will break! When I descended the mountain, I became super strong!? Before I knew it, I’m “S-rank”??? He became unparalleled before realizing it! He beats up villains, monsters, and the Dragon King. The romance and adventure of the strongest hero, Wazu!! | C28: Action, Adventure, Comedy, Drama, Fantasy, Harem, Romance | D28: That Person. Later on… その者。のちに… | E28: Light Novel, Action, Adventure, Comedy, Drama, Fantasy, Harem, Romance, Adapted to Manga, Beastkin, Childhood Friends, Demon Lord, Demons, Dense Protagonist, Dragons, Elves, Emotionally Weak Protagonist, Goddesses, Male Protagonist, Monsters, Multiple POV, Overpowered Protagonist, Polygamy, Schemes And Conspiracies, Sword And Magic, Unrequited Love, Weak to Strong, Japanese, NAHAaTO, ナハァト, Miya Kazutomo, 三弥カズトモ, Earth Star Entertainment, That Person. Later on…, | F28: https://www.novelupdates.com/series/sono-mono-nochi-ni-ln/
A29: The Evil Wizard’s Reformation | B29: A nobody salaryman reincarnates as a notorious villainous wizard!? Sato had been ground down by overwork and meager pay in the modern world, exploited by everyone around him for being a “nice guy.” Then one day, he woke up to find himself in another world entirely. And not just anywhere in that world — he found himself inside the Storm Tower, home of the most feared being in the land: “Prospero the Evil Wizard.” Before he could even make sense of the situation, Sato was more or less forcibly thrust into the role of Prospero himself. Completely bewildered and desperate to get back to his old life as soon as possible, Sato nevertheless can’t bring himself to turn away a visitor who has come seeking Prospero — and before he knows it, he’s setting off on a journey alongside Ariel, a foul-mouthed fairy, to sort out the visitor’s troubles. He gets targeted by the daughter of a demon clan. He gets captured by ruthless, villainous pirates. Throughout this wild, turbulent journey across another world, Sato is absolutely certain he’s been acting like a “nice guy” — and yet, through no intention of his own, his fearsome reputation as a villain only grows more polished with every step. But then, a single fateful encounter shakes Sato’s path to its very core——. A misunderstanding-filled, misconception-fueled adventure fantasy, starring a villainous wizard who can’t quite live up to his own legend. | C29: Adventure, Comedy, Drama, Fantasy, Seinen | D29: Akuyaku mahōtsukai no kaishin The Evil Wizard’s Reformation (Light Novel) 悪役魔法使いの改心 | E29: Light Novel, Adventure, Comedy, Drama, Fantasy, Seinen, Fantasy World, Magic, Male Protagonist, Misunderstandings, Modern Knowledge, Transmigration, Japanese, 風見鶏, Toi8, MFブックス | F29: https://www.novelupdates.com/series/the-evil-wizards-reformation/
A30: We Two Losers Absolutely, Positively Have to Be Happy! | B30: Watanuki Amou, who finally became lovers with his long-time crush and childhood friend Washizaki Karen—witnessed Karen’s cheating scene just one month into dating! Furthermore, the grade’s number one cool beauty, Mamiya Sachika, barged into the scene and punched the man she was cheating with!? Upon hearing the circumstances, it turns out the man she was cheating with is Sachika’s fiancé. Perhaps out of sympathy for being similarly betrayed, Sachika proposes a pseudo-romance to Amou. The pseudo-romance with Sachika, which began with the idea of healing their wounds by doing things—even just for show—that they couldn’t do with their respective partners, is filled with a sense of fulfillment that’s hard to believe is a lie!? Is this the opening of a heartbreaking rom-com!? | C30: Comedy, Psychological, Romance, School Life, Slice of Life | D30: 負け犬同士はぜぇぇぇぇぇったいに幸せにならなくちゃいけない! | E30: Light Novel, Comedy, Psychological, Romance, School Life, Slice of Life, Male Protagonist, Netorare, Japanese, としぞう, あろあ, Kadokawa | F30: https://www.novelupdates.com/series/we-two-losers-absolutely-positively-have-to-be-happy/
A31: The Villainous Aristocrat Dominates with Humility and Honesty ~Using Original Knowledge and the Unique Magic to Avoid the Ruin End (LN) | B31: Hollow von Heisenberg is the villainous aristocrat of the smash-hit RPG Ronzolquia. Gifted with peerless talent in the blade, the arcane, and the arts, he is technically the game’s most powerful character—yet his sloth and arrogance are his undoing. Overconfident in his natural abilities and allergic to hard work, he is a man doomed to die in every single branch of the story. And of all the luck, that is the character I’ve been reincarnated as. “If I stay on this path, I’m as good as dead,” I muttered. “The ‘scenario’—this world’s pre-established harmony—is going to kill me…” …Like hell I’ll let that happen! I’ll use my knowledge of the game to craft a serious meta-build and master my Unique Magic: until every enemy attack is rendered useless! By staying humble, staying sincere, and putting in the damn work, I’m going to survive this ruinous ending no matter what! The smash-hit, next-generation reincarnation fantasy is finally in print! | C31: Action, Adventure, Fantasy, Harem, Shounen, Supernatural | D31: 極悪貴族、謙虚堅実に無双する ～原作知識と固有魔法＜虚空＞を駆使して、破滅エンドを回避します～ | E31: Light Novel, Action, Adventure, Fantasy, Harem, Shounen, Supernatural, Academy, Battle Academy, Beautiful Female Lead, Magic, Male Protagonist, Overpowered Protagonist, Reincarnated in a Game World, Japanese, 月島 秀一, しずま よしのり, Kadokawa | F31: https://www.novelupdates.com/series/the-villainous-aristocrat-dominates-with-humility-and-honesty-using-original-knowledge-and-the-unique-magic-to-avoid-the-ruin-end-ln/
... A61: Once I Became Friends with Hoshigasaki-san, the Cutest Girl in My Grade, She Won’t Stop Clinging to Me Every Day | B61: “W-Will you… b-be friends with me—?” Their friendship began with those unexpected words from Hoshigasaki Hina, the girl rumored to be the cutest in their grade. But while she acted bright and cheerful in public, she was secretly a “disappointing” beauty with absolutely zero self-confidence……? “I… want a friend… -gasaki…” After discovering the real Hoshigasaki-san and starting a secret relationship, her sense of personal distance was, for some reason, completely skewed. She invited him to a sleepover for just the two of them to “deepen their bond,” and the messages on his smartphone never stopped… This is a “broken-distance” slow-burn sweet rom-com about the non-stop clinginess of Hoshigasaki-san—a girl who was (a little?) heavy, but actually incredibly shy! | C61: Comedy, Romance, School Life | D61: 学年で一番かわいい星ヶ崎さんと友だちになったら毎日密着が止まらない | E61: Light Novel, Comedy, Romance, School Life, Japanese, 五十嵐 雄策, たん旦, Kadokawa | F61: https://www.novelupdates.com/series/once-i-became-friends-with-hoshigasaki-san-the-cutest-girl-in-my-grade-she-wont-stop-clinging-to-me-every-day/
A62: About the Reckless Girl Who Kept Challenging a Reborn Man Like Me | B62: “A prodigy at ten, a genius at fifteen, a common man past twenty.” This is a story of the struggle of an ordinary guy like me who is a “reincarnator” and a reckless and promising girl who is a “genius”. | C62: Drama, Fantasy, Romance, School Life, Shounen, Slice of Life | D62: Tenseisha de Aru Watashi ni Idonde Kuru Mubou de Yubou na Shoujo no Hanashi เกิดใหม่ทั้งที ต้องมีเธอเป็นคู่ปรับ 転生者である私に挑んでくる無謀で有望な少女の話 転生者の私に挑んでくる無謀で有望な少女の話 | E62: Light Novel, Drama, Fantasy, Romance, School Life, Shounen, Slice of Life, Age Progression, Alternate World, Appearance Different from Actual Age, Beautiful Female Lead, Calm Protagonist, Caring Protagonist, Childhood Friends, Childhood Love, Chuunibyou, Clingy Lover, College/University, Depression, Devoted Love Interests, Doting Love Interests, Fantasy World, First Love, Genius Protagonist, Hard-Working Protagonist, Helpful Protagonist, Indecisive Protagonist, Love Interest Falls in Love First, Love Rivals, Magic, Male Protagonist, Marriage, Modern Day, Past Trauma, Previous Life Talent, Rivalry, Second Chance, Teachers, Time Skip, Time Travel, Tomboyish Female Lead, Japanese, Kohigashi Nora, 小東のら, Kazuharu Kina, 和遥キナ, Shufunotomosha, Syosetu, Our Second Master, I Got Reincarnated And Mistaken As A Genius?, Love Me Again, Observation Record of a Self-proclaimed Villainess’ Fiance, Can’t Hide My Feelings, My Ears Say They Want to Know You, | F62: https://www.novelupdates.com/series/about-the-reckless-girl-who-kept-challenging-a-reborn-man-like-me/ | G62: 39
A63: Drop Dead, My Beloved Mages | B63: The “School Islands”—a floating city where over a thousand magic academies compete, perched on the boundary between our world and the next. There is only one rule here: use any means necessary to push your academy to the top of the rankings. “I’m going to spend a youth that’s beyond the ordinary here in these islands!” Kuro, a boy with extraordinary powers who was exiled from Earth, enrolls in the Royal Tritonis Academy. However, the once-prestigious school is now on the brink of closure. The only students remaining are three girls, each more eccentric than the last. In a place that holds everything “fantasy” has to offer, a non-standard, high-octane school battle fantasy begins! | C63: Action, Fantasy, Harem, Romance, School Life, Shounen, Supernatural | D63: くたばれ愛しの魔術師ども | E63: Light Novel, Action, Fantasy, Harem, Romance, School Life, Shounen, Supernatural, Academy, Alternate World, Battle Academy, Beautiful Female Lead, Betrayal, Caring Protagonist, Childhood Friends, Determined Protagonist, Fantasy World, Gate to Another World, Hidden Abilities, Magic, Male Protagonist, Naive Protagonist, Royalty, Schemes And Conspiracies, Strong Love Interests, Vampires, Japanese, 佐藤真登, ニリツ, GA Bunko | F63: https://www.novelupdates.com/series/drop-dead-my-beloved-mages/
A64: Kanojo no ane wa 2-shū-me no kanojo | B64: “I’ll be waiting in the future.” A promise like that… it’s just impossible. ​Shibukawa Ryuuichi’s life changes the moment he steps into the home of his girlfriend, Asada Miharu, and meets her twin sister, Sayuki. Unlike the earnest, innocent girl he’s dating, Sayuki carries an aura of sophisticated maturity—and she has a secret that defies logic. ​『Actually… I’m the “Miharu” from the future.』 ​Sayuki explains the unthinkable: she is a version of Miharu who time-leaped, reincarnating as her own twin sister to repeat her life. In that first loop, she and Ryuuichi drifted apart until their relationship shattered. Now, she’s back with a mission. ​『We failed each other once. So, I want you to practice with me… that way, you won’t have to lose her this time.』 ​Overwhelmed by her ability to predict every coming event with terrifying accuracy, Ryuuichi is forced into a secret, co-dependent pact. But Sayuki’s “guidance” is far from innocent. Armed with future knowledge of his deepest desires and every hidden preference, she uses her “pre-studied” love to launch a meticulous, seductive assault on his senses. ​Caught between his pure-hearted girlfriend and the sister who knows his soul better than he does himself, Ryuuichi find himself drowning in a temptation he can’t resist. | C64: Drama, Harem, Romance, School Life, Supernatural | D64: 彼女の姉は２周目の彼女 | E64: Light Novel, Drama, Harem, Romance, School Life, Supernatural, Beautiful Female Lead, Male Protagonist, Modern Day, Reincarnation, Time Loop, Twins, Japanese, 眞田, ういり, MF Bunko | F64: https://www.novelupdates.com/series/kanojo-no-ane-wa-2-shu-me-no-kanojo/
A65: I’m Actually a Girl, You Know? | B65: A sweet and flirtatious romcom spun with the best ex-“guy friend” who is easygoing and on the exact same wavelength! Hayate, a handsome boy junior one year younger than me. Being easy to talk to and on the same wavelength, we hit it off the moment we met. Huddling shoulder-to-shoulder to watch anime on a single smartphone, getting hugged, or even sharing indirect kisses—none of it was a problem if we were just friends. …But, he feels strangely soft and nice to the touch. That’s because this guy is—— Even after it was revealed that Hayate wasn’t a handsome boy but a “beautiful girl,” we still ate lunch together and hung out after school just like usual. Furthermore, she proposed a date to cure my distrust of women, and the distance between Hayate and I is closing rapidly!? “Since it’s me, your ‘guy friend,’ it’s okay to touch me more, right?” With the sense of distance remaining like that of guy friends, I am going to be made increasingly aware that Hayate is a “girl,” and a cute, special one at that. Plus, the [Digital Special Edition] includes a newly written episode! | C65: Comedy, Drama, Harem, Romance, School Life, Slice of Life | D65: Watashi, Kore de mo Onnanoko nan su yo? わたし、コレでも女の子なんすよ? | E65: Light Novel, Comedy, Drama, Harem, Romance, School Life, Slice of Life, Androgynous Characters, Male Protagonist, Modern Day, Japanese, Shijou Kanata, 四条 彼方, Unapoppo, Kadokawa | F65: https://www.novelupdates.com/series/im-actually-a-girl-you-know/
A66: Adventures of a Runemaster | B66: 「Paying with your body──are you really okay with this kind of 『contract』?」 Let’s begin a hard erot*c fantasy story woven by runes. | C66: Action, Adult, Ecchi, Fantasy, Harem, Mature, Psychological, Romance | D66: Haburare Rune-tsukai no Isekai Boukentan ハブられルーン使いの異世界冒険譚 | E66: Light Novel, Action, Adult, Ecchi, Fantasy, Harem, Mature, Psychological, Romance, Adapted to Manga, Adventurers, Cold Protagonist, Cunning Protagonist, Depictions of Cruelty, Dungeons, Magic, Revenge, Transported to Another World, Japanese, 黄金の黒山羊, Kikuchi Seiji, 菊池 政治, GC Novels, GCN Bunko, Micro Magazine | F66: https://www.novelupdates.com/series/adventures-of-a-runemaster/
A67: Transferred to Another World and Became a Teacher, But I’m Feared as a Witch | B67: The Strongest Rookie Female Teacher Breaks Through the Academy’s Old Ways!? Aoi, who was a school teacher, suddenly found herself transported to another world. Rescued by a sage of the forest, she was taught magic. Having mastered it in no time, she was recommended to join the world’s largest magic academy as a teacher to further her studies. However, the academy was plagued with troublemakers from noble families who even the teachers couldn’t handle… “Royalty? Nobility? It doesn’t matter. Students who misbehave too much will be punished.” With her overwhelming magical prowess, Aoi casually instructs her students. But as she does so, she begins to be called a “witch” and feared by others. | C67: Action, Adventure, Comedy, Fantasy, Romance, School Life, Shoujo, Slice of Life | D67: Isekai Teni Shite Kyoushi ni Nattaga, Majo to Osorerarete Iru Ken The Fearsome Witch Teaches in Another World [Official] 異世界転移して教師になったが, 魔女と恐れられている件 | E67: Light Novel, Action, Adventure, Comedy, Fantasy, Romance, School Life, Shoujo, Slice of Life, Academy, Adapted to Manga, Artifacts, Beastkin, Calm Protagonist, Dragons, Dwarfs, Elemental Magic, Elves, Fantasy World, Female Protagonist, Kingdoms, Lack of Common Sense, Magic, Magic Formations, Magical Technology, Nobles, Overpowered Protagonist, Protagonist Strong from the Start, Reincarnated in Another World, Royalty, Teachers, Japanese, Inoue Mitsuru, 井上みつる, 鈴ノ, Earth Star Novel, アース-スター エンターテイメント, J-Novel Club | F67: https://www.novelupdates.com/series/transferred-to-another-world-and-became-a-teacher-but-im-feared-as-a-witch/
A68: Goodbye, Fairy | B68: April, 1991. The sudden appearance of a single girl taking shelter from the rain brought us days upon days of endless wonder. Her name was Maja, and she came from a faraway land. Since that moment, we spent our days with her, each one bounding with mystery. After she returned to her country, however, was when our greatest mystery began, and the key to solving it rests somewhere within our memories. This is the story of an unforgettable meeting and a prayer. First book in the Beruf series. | C68: Mystery, Psychological | D68: Beruf Series I - Goodbye, Fairy Sayonara Yousei さよなら妖精 | E68: Light Novel, Mystery, Psychological, Japanese, Yonezawa Honobu, Tokyo Sogensha, Hyouka | F68: https://www.novelupdates.com/series/goodbye-fairy/
